-------------------- Log Start | Sun May 26 05:10:09 2024 --------------------
platform: Linux-6.1.21-v7+-armv7l-with-glibc2.31
data_path: /home/m/printer_data
is_default_data_path: False
config_file: /home/m/printer_data/config/moonraker.conf
startup_warnings: []
verbose: False
debug: False
asyncio_debug: False
is_backup_config: False
is_python_package: True
instance_uuid: 2789442f2e9a445a89964c1bbf7d3a06
unix_socket_path: /home/m/printer_data/comms/moonraker.sock
software_version: v0.8.0-343-g0f2e3d7
git_branch: master
git_remote: origin
git_repo_url: https://github.com/Arksine/moonraker.git
modified_files: []
unofficial_components: []
log_file: /home/m/printer_data/logs/moonraker.log
python_version: 3.9.2 (default, Mar 12 2021, 04:06:34)  [GCC 10.2.1 20210110]
launch_args: /home/m/moonraker-env/bin/python /home/m/moonraker/moonraker/__main__.py -d /home/m/printer_data
msgspec_enabled: False
uvloop_enabled: False

#################### Moonraker Configuration ####################

[server]
host = 0.0.0.0
port = 7125
max_upload_size = 1024
klippy_uds_address = ~/printer_data/comms/klippy.sock

[file_manager]
enable_object_processing = True

[authorization]
cors_domains = 
	https://my.mainsail.xyz
	http://my.mainsail.xyz
	http://*.local
	http://*.lan
	http://*.m01.cl
trusted_clients = 
	172.22.0.0/16
	10.0.0.0/8
	127.0.0.0/8
	169.254.0.0/16
	172.16.0.0/12
	192.168.0.0/16
	FE80::/10
	::1/128

[octoprint_compat]

[history]

[announcements]
subscriptions = 
	mainsail

[update_manager]
refresh_interval = 168
enable_auto_refresh = True

[update_manager mainsail]
type = web
channel = stable
repo = mainsail-crew/mainsail
path = ~/mainsail

[update_manager mainsail-config]
type = git_repo
primary_branch = master
path = ~/mainsail-config
origin = https://github.com/mainsail-crew/mainsail-config.git
managed_services = klipper

[update_manager crowsnest]
type = git_repo
path = ~/crowsnest
origin = https://github.com/mainsail-crew/crowsnest.git
managed_services = crowsnest
install_script = tools/pkglist.sh

[update_manager sonar]
type = git_repo
path = ~/sonar
origin = https://github.com/mainsail-crew/sonar.git
primary_branch = main
managed_services = sonar
install_script = tools/install.sh

[power printer]
type = gpio
pin = gpiochip0/gpio23
locked_while_printing = True
on_when_job_queued = True
restart_klipper_when_powered = True
restart_delay = 2
bound_service = klipper

[update_manager client moonraker-telegram-bot]
type = git_repo
path = ~/moonraker-telegram-bot
origin = https://github.com/nlef/moonraker-telegram-bot.git
env = ~/moonraker-telegram-bot-env/bin/python
requirements = scripts/requirements.txt
install_script = scripts/install.sh

[update_manager Klipper-Adaptive-Meshing-Purging]
type = git_repo
channel = dev
path = ~/Klipper-Adaptive-Meshing-Purging
origin = https://github.com/kyleisah/Klipper-Adaptive-Meshing-Purging.git
managed_services = klipper
primary_branch = main

#################################################################
All Configuration Files:
/home/m/printer_data/config/moonraker.conf
#################################################################

Database Versions: pylmdb = 1.4.1, lmdb = (0, 9, 29)
Unsafe Shutdown Count: 31

System Info:

***python***
  version: (3, 9, 2, 'final', 0)
  version_string: 3.9.2 (default, Mar 12 2021, 04:06:34)  [GCC 10.2.1 20210110]

***cpu_info***
  cpu_count: 4
  bits: 32bit
  processor: armv7l
  cpu_desc: ARMv7 Processor rev 4 (v7l)
  serial_number: 1186635f
  hardware_desc: BCM2835
  model: Raspberry Pi 3 Model B Plus Rev 1.3
  total_memory: 891696
  memory_units: kB

***sd_info***
  manufacturer_id: 03
  manufacturer: Sandisk
  oem_id: 5344
  product_name: SC32G
  product_revision: 8.0
  serial_number: 7c983a54
  manufacturer_date: 12/2018
  capacity: 29.7 GiB
  total_bytes: 31914983424

***distribution***
  name: Raspbian GNU/Linux 11 (bullseye)
  id: raspbian
  version: 11
  version_parts: {'major': '11', 'minor': '', 'build_number': ''}
  like: debian
  codename: bullseye
  release_info: {'name': 'MainsailOS', 'version_id': '1.2.1', 'codename': 'bullseye', 'id': 'mainsailos'}
  kernel_version: 6.1.21-v7+

***virtualization***
  virt_type: none
  virt_identifier: none

***network***

***canbus***

***Allowed Services***
  klipper_mcu
  webcamd
  MoonCord
  KlipperScreen
  moonraker-telegram-bot
  moonraker-obico
  sonar
  crowsnest
  octoeverywhere
  ratos-configurator
Found libcamera Python module, version: v0.0.5+83-bde9b04f

Systemd unit moonraker.service:
unit_name: moonraker.service
is_default: True
manager: systemd
Properties:
**Requires=['network-online.target', 'system.slice', 'sysinit.target']
**After=['systemd-journald.socket', 'sysinit.target', 'system.slice', 'network-online.target', 'klipper.service', 'basic.target']
**SupplementaryGroups=['moonraker-admin']
**EnvironmentFiles=/home/m/printer_data/systemd/moonraker.env
**ExecStart=/home/m/moonraker-env/bin/python $MOONRAKER_ARGS
**WorkingDirectory=
**FragmentPath=/etc/systemd/system/moonraker.service
**Description=API Server for Klipper SV1
**User=m

Systemd unit klipper.service:
unit_name: klipper.service
is_default: True
manager: systemd
Properties:
**Requires=['system.slice', '-.mount', 'sysinit.target']
**After=['systemd-journald.socket', 'sysinit.target', 'system.slice', 'network-online.target', '-.mount', 'klipper-mcu.service', 'basic.target']
**SupplementaryGroups=[]
**EnvironmentFiles=/home/m/printer_data/systemd/klipper.env
**ExecStart=/home/m/klippy-env/bin/python $KLIPPER_ARGS
**WorkingDirectory=/home/m/klipper
**FragmentPath=/etc/systemd/system/klipper.service
**Description=Klipper 3D Printer Firmware SV1
**User=m
Git Repo moonraker: Warnings detected:
  Repo has untracked source files: ['moonraker/components/timelapse.py']
Git Repo klipper: Warnings detected:
  Repo is corrupt
  Repo has untracked source files: ['klippy/extras/fcm.py']
Git Repo mainsail-config: No warnings detected
Git Repo crowsnest: No warnings detected
Git Repo sonar: No warnings detected
Git Repo moonraker-telegram-bot: No warnings detected
Git Repo Klipper-Adaptive-Meshing-Purging: No warnings detected
Klipper Version: v0.12.0-178-g7e8c7f46-dirty
2024-05-26 01:10:09,887 [announcements.py:_fetch_moonlight()] - Failed to update subscription 'moonraker': Timeout while connecting
2024-05-26 01:10:36,922 [announcements.py:_fetch_moonlight()] - Failed to update subscription 'klipper': Timeout while connecting
2024-05-26 01:11:03,941 [announcements.py:_fetch_moonlight()] - Failed to update subscription 'mainsail': Timeout while connecting
2024-05-26 01:11:30,962 [announcements.py:_fetch_moonlight()] - Failed to update subscription 'moonraker-telegram-bot': Timeout while connecting
2024-05-26 01:40:09,881 [announcements.py:_fetch_moonlight()] - Failed to update subscription 'moonraker': Timeout while connecting
2024-05-26 01:40:36,897 [announcements.py:_fetch_moonlight()] - Failed to update subscription 'klipper': Timeout while connecting
2024-05-26 01:41:03,914 [announcements.py:_fetch_moonlight()] - Failed to update subscription 'mainsail': Timeout while connecting
2024-05-26 01:41:30,931 [announcements.py:_fetch_moonlight()] - Failed to update subscription 'moonraker-telegram-bot': Timeout while connecting
2024-05-26 02:10:09,884 [announcements.py:_fetch_moonlight()] - Failed to update subscription 'moonraker': Timeout while connecting
2024-05-26 02:10:36,900 [announcements.py:_fetch_moonlight()] - Failed to update subscription 'klipper': Timeout while connecting
2024-05-26 02:11:03,919 [announcements.py:_fetch_moonlight()] - Failed to update subscription 'mainsail': Timeout while connecting
2024-05-26 02:11:30,935 [announcements.py:_fetch_moonlight()] - Failed to update subscription 'moonraker-telegram-bot': Timeout while connecting
2024-05-26 03:10:09,886 [announcements.py:_fetch_moonlight()] - Failed to update subscription 'moonraker': Timeout while connecting
2024-05-26 03:10:22,918 [ioloop.py:_run_callback()] - Exception in callback functools.partial(<function _HTTPConnection.__init__.<locals>.<lambda> at 0x655b8b20>, <Task finished name='Task-9283612' coro=<_HTTPConnection.run() done, defined at /home/m/moonraker-env/lib/python3.9/site-packages/tornado/simple_httpclient.py:290> exception=gaierror(-3, 'Temporary failure in name resolution')>)
Traceback (most recent call last):
  File "/home/m/moonraker-env/lib/python3.9/site-packages/tornado/ioloop.py", line 750, in _run_callback
    ret = callback()
  File "/home/m/moonraker-env/lib/python3.9/site-packages/tornado/simple_httpclient.py", line 287, in <lambda>
    gen.convert_yielded(self.run()), lambda f: f.result()
  File "/home/m/moonraker-env/lib/python3.9/site-packages/tornado/simple_httpclient.py", line 340, in run
    stream = await self.tcp_client.connect(
  File "/home/m/moonraker-env/lib/python3.9/site-packages/tornado/tcpclient.py", line 269, in connect
    addrinfo = await self.resolver.resolve(host, port, af)
  File "/home/m/moonraker-env/lib/python3.9/site-packages/tornado/netutil.py", line 433, in resolve
    for fam, _, _, _, address in await asyncio.get_running_loop().getaddrinfo(
  File "/usr/lib/python3.9/asyncio/base_events.py", line 856, in getaddrinfo
    return await self.run_in_executor(
  File "/usr/lib/python3.9/concurrent/futures/thread.py", line 52, in run
    result = self.fn(*self.args, **self.kwargs)
  File "/usr/lib/python3.9/socket.py", line 953, in getaddrinfo
    for res in _socket.getaddrinfo(host, port, family, type, proto, flags):
socket.gaierror: [Errno -3] Temporary failure in name resolution
2024-05-26 03:10:28,417 [ioloop.py:_run_callback()] - Exception in callback functools.partial(<function _HTTPConnection.__init__.<locals>.<lambda> at 0x655b8340>, <Task finished name='Task-9283684' coro=<_HTTPConnection.run() done, defined at /home/m/moonraker-env/lib/python3.9/site-packages/tornado/simple_httpclient.py:290> exception=gaierror(-3, 'Temporary failure in name resolution')>)
Traceback (most recent call last):
  File "/home/m/moonraker-env/lib/python3.9/site-packages/tornado/ioloop.py", line 750, in _run_callback
    ret = callback()
  File "/home/m/moonraker-env/lib/python3.9/site-packages/tornado/simple_httpclient.py", line 287, in <lambda>
    gen.convert_yielded(self.run()), lambda f: f.result()
  File "/home/m/moonraker-env/lib/python3.9/site-packages/tornado/simple_httpclient.py", line 340, in run
    stream = await self.tcp_client.connect(
  File "/home/m/moonraker-env/lib/python3.9/site-packages/tornado/tcpclient.py", line 269, in connect
    addrinfo = await self.resolver.resolve(host, port, af)
  File "/home/m/moonraker-env/lib/python3.9/site-packages/tornado/netutil.py", line 433, in resolve
    for fam, _, _, _, address in await asyncio.get_running_loop().getaddrinfo(
  File "/usr/lib/python3.9/asyncio/base_events.py", line 856, in getaddrinfo
    return await self.run_in_executor(
  File "/usr/lib/python3.9/concurrent/futures/thread.py", line 52, in run
    result = self.fn(*self.args, **self.kwargs)
  File "/usr/lib/python3.9/socket.py", line 953, in getaddrinfo
    for res in _socket.getaddrinfo(host, port, family, type, proto, flags):
socket.gaierror: [Errno -3] Temporary failure in name resolution
2024-05-26 03:10:33,915 [ioloop.py:_run_callback()] - Exception in callback functools.partial(<function _HTTPConnection.__init__.<locals>.<lambda> at 0x655b82b0>, <Task finished name='Task-9283760' coro=<_HTTPConnection.run() done, defined at /home/m/moonraker-env/lib/python3.9/site-packages/tornado/simple_httpclient.py:290> exception=gaierror(-3, 'Temporary failure in name resolution')>)
Traceback (most recent call last):
  File "/home/m/moonraker-env/lib/python3.9/site-packages/tornado/ioloop.py", line 750, in _run_callback
    ret = callback()
  File "/home/m/moonraker-env/lib/python3.9/site-packages/tornado/simple_httpclient.py", line 287, in <lambda>
    gen.convert_yielded(self.run()), lambda f: f.result()
  File "/home/m/moonraker-env/lib/python3.9/site-packages/tornado/simple_httpclient.py", line 340, in run
    stream = await self.tcp_client.connect(
  File "/home/m/moonraker-env/lib/python3.9/site-packages/tornado/tcpclient.py", line 269, in connect
    addrinfo = await self.resolver.resolve(host, port, af)
  File "/home/m/moonraker-env/lib/python3.9/site-packages/tornado/netutil.py", line 433, in resolve
    for fam, _, _, _, address in await asyncio.get_running_loop().getaddrinfo(
  File "/usr/lib/python3.9/asyncio/base_events.py", line 856, in getaddrinfo
    return await self.run_in_executor(
  File "/usr/lib/python3.9/concurrent/futures/thread.py", line 52, in run
    result = self.fn(*self.args, **self.kwargs)
  File "/usr/lib/python3.9/socket.py", line 953, in getaddrinfo
    for res in _socket.getaddrinfo(host, port, family, type, proto, flags):
socket.gaierror: [Errno -3] Temporary failure in name resolution
2024-05-26 03:10:36,906 [announcements.py:_fetch_moonlight()] - Failed to update subscription 'klipper': Timeout while connecting
2024-05-26 03:10:44,427 [ioloop.py:_run_callback()] - Exception in callback functools.partial(<function _HTTPConnection.__init__.<locals>.<lambda> at 0x655b8f10>, <Task finished name='Task-9283824' coro=<_HTTPConnection.run() done, defined at /home/m/moonraker-env/lib/python3.9/site-packages/tornado/simple_httpclient.py:290> exception=gaierror(-3, 'Temporary failure in name resolution')>)
Traceback (most recent call last):
  File "/home/m/moonraker-env/lib/python3.9/site-packages/tornado/ioloop.py", line 750, in _run_callback
    ret = callback()
  File "/home/m/moonraker-env/lib/python3.9/site-packages/tornado/simple_httpclient.py", line 287, in <lambda>
    gen.convert_yielded(self.run()), lambda f: f.result()
  File "/home/m/moonraker-env/lib/python3.9/site-packages/tornado/simple_httpclient.py", line 340, in run
    stream = await self.tcp_client.connect(
  File "/home/m/moonraker-env/lib/python3.9/site-packages/tornado/tcpclient.py", line 269, in connect
    addrinfo = await self.resolver.resolve(host, port, af)
  File "/home/m/moonraker-env/lib/python3.9/site-packages/tornado/netutil.py", line 433, in resolve
    for fam, _, _, _, address in await asyncio.get_running_loop().getaddrinfo(
  File "/usr/lib/python3.9/asyncio/base_events.py", line 856, in getaddrinfo
    return await self.run_in_executor(
  File "/usr/lib/python3.9/concurrent/futures/thread.py", line 52, in run
    result = self.fn(*self.args, **self.kwargs)
  File "/usr/lib/python3.9/socket.py", line 953, in getaddrinfo
    for res in _socket.getaddrinfo(host, port, family, type, proto, flags):
socket.gaierror: [Errno -3] Temporary failure in name resolution
2024-05-26 03:10:49,931 [ioloop.py:_run_callback()] - Exception in callback functools.partial(<function _HTTPConnection.__init__.<locals>.<lambda> at 0x655b8ec8>, <Task finished name='Task-9283905' coro=<_HTTPConnection.run() done, defined at /home/m/moonraker-env/lib/python3.9/site-packages/tornado/simple_httpclient.py:290> exception=gaierror(-3, 'Temporary failure in name resolution')>)
Traceback (most recent call last):
  File "/home/m/moonraker-env/lib/python3.9/site-packages/tornado/ioloop.py", line 750, in _run_callback
    ret = callback()
  File "/home/m/moonraker-env/lib/python3.9/site-packages/tornado/simple_httpclient.py", line 287, in <lambda>
    gen.convert_yielded(self.run()), lambda f: f.result()
  File "/home/m/moonraker-env/lib/python3.9/site-packages/tornado/simple_httpclient.py", line 340, in run
    stream = await self.tcp_client.connect(
  File "/home/m/moonraker-env/lib/python3.9/site-packages/tornado/tcpclient.py", line 269, in connect
    addrinfo = await self.resolver.resolve(host, port, af)
  File "/home/m/moonraker-env/lib/python3.9/site-packages/tornado/netutil.py", line 433, in resolve
    for fam, _, _, _, address in await asyncio.get_running_loop().getaddrinfo(
  File "/usr/lib/python3.9/asyncio/base_events.py", line 856, in getaddrinfo
    return await self.run_in_executor(
  File "/usr/lib/python3.9/concurrent/futures/thread.py", line 52, in run
    result = self.fn(*self.args, **self.kwargs)
  File "/usr/lib/python3.9/socket.py", line 953, in getaddrinfo
    for res in _socket.getaddrinfo(host, port, family, type, proto, flags):
socket.gaierror: [Errno -3] Temporary failure in name resolution
2024-05-26 03:10:54,936 [ioloop.py:_run_callback()] - Exception in callback functools.partial(<function _HTTPConnection.__init__.<locals>.<lambda> at 0x655b8c88>, <Task finished name='Task-9283971' coro=<_HTTPConnection.run() done, defined at /home/m/moonraker-env/lib/python3.9/site-packages/tornado/simple_httpclient.py:290> exception=gaierror(-3, 'Temporary failure in name resolution')>)
Traceback (most recent call last):
  File "/home/m/moonraker-env/lib/python3.9/site-packages/tornado/ioloop.py", line 750, in _run_callback
    ret = callback()
  File "/home/m/moonraker-env/lib/python3.9/site-packages/tornado/simple_httpclient.py", line 287, in <lambda>
    gen.convert_yielded(self.run()), lambda f: f.result()
  File "/home/m/moonraker-env/lib/python3.9/site-packages/tornado/simple_httpclient.py", line 340, in run
    stream = await self.tcp_client.connect(
  File "/home/m/moonraker-env/lib/python3.9/site-packages/tornado/tcpclient.py", line 269, in connect
    addrinfo = await self.resolver.resolve(host, port, af)
  File "/home/m/moonraker-env/lib/python3.9/site-packages/tornado/netutil.py", line 433, in resolve
    for fam, _, _, _, address in await asyncio.get_running_loop().getaddrinfo(
  File "/usr/lib/python3.9/asyncio/base_events.py", line 856, in getaddrinfo
    return await self.run_in_executor(
  File "/usr/lib/python3.9/concurrent/futures/thread.py", line 52, in run
    result = self.fn(*self.args, **self.kwargs)
  File "/usr/lib/python3.9/socket.py", line 953, in getaddrinfo
    for res in _socket.getaddrinfo(host, port, family, type, proto, flags):
socket.gaierror: [Errno -3] Temporary failure in name resolution
2024-05-26 03:11:00,431 [ioloop.py:_run_callback()] - Exception in callback functools.partial(<function _HTTPConnection.__init__.<locals>.<lambda> at 0x6556f028>, <Task finished name='Task-9284029' coro=<_HTTPConnection.run() done, defined at /home/m/moonraker-env/lib/python3.9/site-packages/tornado/simple_httpclient.py:290> exception=gaierror(-3, 'Temporary failure in name resolution')>)
Traceback (most recent call last):
  File "/home/m/moonraker-env/lib/python3.9/site-packages/tornado/ioloop.py", line 750, in _run_callback
    ret = callback()
  File "/home/m/moonraker-env/lib/python3.9/site-packages/tornado/simple_httpclient.py", line 287, in <lambda>
    gen.convert_yielded(self.run()), lambda f: f.result()
  File "/home/m/moonraker-env/lib/python3.9/site-packages/tornado/simple_httpclient.py", line 340, in run
    stream = await self.tcp_client.connect(
  File "/home/m/moonraker-env/lib/python3.9/site-packages/tornado/tcpclient.py", line 269, in connect
    addrinfo = await self.resolver.resolve(host, port, af)
  File "/home/m/moonraker-env/lib/python3.9/site-packages/tornado/netutil.py", line 433, in resolve
    for fam, _, _, _, address in await asyncio.get_running_loop().getaddrinfo(
  File "/usr/lib/python3.9/asyncio/base_events.py", line 856, in getaddrinfo
    return await self.run_in_executor(
  File "/usr/lib/python3.9/concurrent/futures/thread.py", line 52, in run
    result = self.fn(*self.args, **self.kwargs)
  File "/usr/lib/python3.9/socket.py", line 953, in getaddrinfo
    for res in _socket.getaddrinfo(host, port, family, type, proto, flags):
socket.gaierror: [Errno -3] Temporary failure in name resolution
2024-05-26 03:11:03,924 [announcements.py:_fetch_moonlight()] - Failed to update subscription 'mainsail': Timeout while connecting
2024-05-26 03:11:05,942 [ioloop.py:_run_callback()] - Exception in callback functools.partial(<function _HTTPConnection.__init__.<locals>.<lambda> at 0x6556f418>, <Task finished name='Task-9284101' coro=<_HTTPConnection.run() done, defined at /home/m/moonraker-env/lib/python3.9/site-packages/tornado/simple_httpclient.py:290> exception=gaierror(-3, 'Temporary failure in name resolution')>)
Traceback (most recent call last):
  File "/home/m/moonraker-env/lib/python3.9/site-packages/tornado/ioloop.py", line 750, in _run_callback
    ret = callback()
  File "/home/m/moonraker-env/lib/python3.9/site-packages/tornado/simple_httpclient.py", line 287, in <lambda>
    gen.convert_yielded(self.run()), lambda f: f.result()
  File "/home/m/moonraker-env/lib/python3.9/site-packages/tornado/simple_httpclient.py", line 340, in run
    stream = await self.tcp_client.connect(
  File "/home/m/moonraker-env/lib/python3.9/site-packages/tornado/tcpclient.py", line 269, in connect
    addrinfo = await self.resolver.resolve(host, port, af)
  File "/home/m/moonraker-env/lib/python3.9/site-packages/tornado/netutil.py", line 433, in resolve
    for fam, _, _, _, address in await asyncio.get_running_loop().getaddrinfo(
  File "/usr/lib/python3.9/asyncio/base_events.py", line 856, in getaddrinfo
    return await self.run_in_executor(
  File "/usr/lib/python3.9/concurrent/futures/thread.py", line 52, in run
    result = self.fn(*self.args, **self.kwargs)
  File "/usr/lib/python3.9/socket.py", line 953, in getaddrinfo
    for res in _socket.getaddrinfo(host, port, family, type, proto, flags):
socket.gaierror: [Errno -3] Temporary failure in name resolution
2024-05-26 03:11:06,441 [ioloop.py:_run_callback()] - Exception in callback functools.partial(<function _HTTPConnection.__init__.<locals>.<lambda> at 0x6681ab68>, <Task finished name='Task-9284170' coro=<_HTTPConnection.run() done, defined at /home/m/moonraker-env/lib/python3.9/site-packages/tornado/simple_httpclient.py:290> exception=gaierror(-3, 'Temporary failure in name resolution')>)
Traceback (most recent call last):
  File "/home/m/moonraker-env/lib/python3.9/site-packages/tornado/ioloop.py", line 750, in _run_callback
    ret = callback()
  File "/home/m/moonraker-env/lib/python3.9/site-packages/tornado/simple_httpclient.py", line 287, in <lambda>
    gen.convert_yielded(self.run()), lambda f: f.result()
  File "/home/m/moonraker-env/lib/python3.9/site-packages/tornado/simple_httpclient.py", line 340, in run
    stream = await self.tcp_client.connect(
  File "/home/m/moonraker-env/lib/python3.9/site-packages/tornado/tcpclient.py", line 269, in connect
    addrinfo = await self.resolver.resolve(host, port, af)
  File "/home/m/moonraker-env/lib/python3.9/site-packages/tornado/netutil.py", line 433, in resolve
    for fam, _, _, _, address in await asyncio.get_running_loop().getaddrinfo(
  File "/usr/lib/python3.9/asyncio/base_events.py", line 856, in getaddrinfo
    return await self.run_in_executor(
  File "/usr/lib/python3.9/concurrent/futures/thread.py", line 52, in run
    result = self.fn(*self.args, **self.kwargs)
  File "/usr/lib/python3.9/socket.py", line 953, in getaddrinfo
    for res in _socket.getaddrinfo(host, port, family, type, proto, flags):
socket.gaierror: [Errno -3] Temporary failure in name resolution
2024-05-26 03:11:11,949 [ioloop.py:_run_callback()] - Exception in callback functools.partial(<function _HTTPConnection.__init__.<locals>.<lambda> at 0x655b8ad8>, <Task finished name='Task-9284226' coro=<_HTTPConnection.run() done, defined at /home/m/moonraker-env/lib/python3.9/site-packages/tornado/simple_httpclient.py:290> exception=gaierror(-3, 'Temporary failure in name resolution')>)
Traceback (most recent call last):
  File "/home/m/moonraker-env/lib/python3.9/site-packages/tornado/ioloop.py", line 750, in _run_callback
    ret = callback()
  File "/home/m/moonraker-env/lib/python3.9/site-packages/tornado/simple_httpclient.py", line 287, in <lambda>
    gen.convert_yielded(self.run()), lambda f: f.result()
  File "/home/m/moonraker-env/lib/python3.9/site-packages/tornado/simple_httpclient.py", line 340, in run
    stream = await self.tcp_client.connect(
  File "/home/m/moonraker-env/lib/python3.9/site-packages/tornado/tcpclient.py", line 269, in connect
    addrinfo = await self.resolver.resolve(host, port, af)
  File "/home/m/moonraker-env/lib/python3.9/site-packages/tornado/netutil.py", line 433, in resolve
    for fam, _, _, _, address in await asyncio.get_running_loop().getaddrinfo(
  File "/usr/lib/python3.9/asyncio/base_events.py", line 856, in getaddrinfo
    return await self.run_in_executor(
  File "/usr/lib/python3.9/concurrent/futures/thread.py", line 52, in run
    result = self.fn(*self.args, **self.kwargs)
  File "/usr/lib/python3.9/socket.py", line 953, in getaddrinfo
    for res in _socket.getaddrinfo(host, port, family, type, proto, flags):
socket.gaierror: [Errno -3] Temporary failure in name resolution
2024-05-26 03:11:16,952 [ioloop.py:_run_callback()] - Exception in callback functools.partial(<function _HTTPConnection.__init__.<locals>.<lambda> at 0x655b8f58>, <Task finished name='Task-9284303' coro=<_HTTPConnection.run() done, defined at /home/m/moonraker-env/lib/python3.9/site-packages/tornado/simple_httpclient.py:290> exception=gaierror(-3, 'Temporary failure in name resolution')>)
Traceback (most recent call last):
  File "/home/m/moonraker-env/lib/python3.9/site-packages/tornado/ioloop.py", line 750, in _run_callback
    ret = callback()
  File "/home/m/moonraker-env/lib/python3.9/site-packages/tornado/simple_httpclient.py", line 287, in <lambda>
    gen.convert_yielded(self.run()), lambda f: f.result()
  File "/home/m/moonraker-env/lib/python3.9/site-packages/tornado/simple_httpclient.py", line 340, in run
    stream = await self.tcp_client.connect(
  File "/home/m/moonraker-env/lib/python3.9/site-packages/tornado/tcpclient.py", line 269, in connect
    addrinfo = await self.resolver.resolve(host, port, af)
  File "/home/m/moonraker-env/lib/python3.9/site-packages/tornado/netutil.py", line 433, in resolve
    for fam, _, _, _, address in await asyncio.get_running_loop().getaddrinfo(
  File "/usr/lib/python3.9/asyncio/base_events.py", line 856, in getaddrinfo
    return await self.run_in_executor(
  File "/usr/lib/python3.9/concurrent/futures/thread.py", line 52, in run
    result = self.fn(*self.args, **self.kwargs)
  File "/usr/lib/python3.9/socket.py", line 953, in getaddrinfo
    for res in _socket.getaddrinfo(host, port, family, type, proto, flags):
socket.gaierror: [Errno -3] Temporary failure in name resolution
2024-05-26 03:11:24,469 [ioloop.py:_run_callback()] - Exception in callback functools.partial(<function _HTTPConnection.__init__.<locals>.<lambda> at 0x64b87898>, <Task finished name='Task-9284340' coro=<_HTTPConnection.run() done, defined at /home/m/moonraker-env/lib/python3.9/site-packages/tornado/simple_httpclient.py:290> exception=gaierror(-3, 'Temporary failure in name resolution')>)
Traceback (most recent call last):
  File "/home/m/moonraker-env/lib/python3.9/site-packages/tornado/ioloop.py", line 750, in _run_callback
    ret = callback()
  File "/home/m/moonraker-env/lib/python3.9/site-packages/tornado/simple_httpclient.py", line 287, in <lambda>
    gen.convert_yielded(self.run()), lambda f: f.result()
  File "/home/m/moonraker-env/lib/python3.9/site-packages/tornado/simple_httpclient.py", line 340, in run
    stream = await self.tcp_client.connect(
  File "/home/m/moonraker-env/lib/python3.9/site-packages/tornado/tcpclient.py", line 269, in connect
    addrinfo = await self.resolver.resolve(host, port, af)
  File "/home/m/moonraker-env/lib/python3.9/site-packages/tornado/netutil.py", line 433, in resolve
    for fam, _, _, _, address in await asyncio.get_running_loop().getaddrinfo(
  File "/usr/lib/python3.9/asyncio/base_events.py", line 856, in getaddrinfo
    return await self.run_in_executor(
  File "/usr/lib/python3.9/concurrent/futures/thread.py", line 52, in run
    result = self.fn(*self.args, **self.kwargs)
  File "/usr/lib/python3.9/socket.py", line 953, in getaddrinfo
    for res in _socket.getaddrinfo(host, port, family, type, proto, flags):
socket.gaierror: [Errno -3] Temporary failure in name resolution
2024-05-26 03:11:29,981 [ioloop.py:_run_callback()] - Exception in callback functools.partial(<function _HTTPConnection.__init__.<locals>.<lambda> at 0x655b87c0>, <Task finished name='Task-9284371' coro=<_HTTPConnection.run() done, defined at /home/m/moonraker-env/lib/python3.9/site-packages/tornado/simple_httpclient.py:290> exception=gaierror(-3, 'Temporary failure in name resolution')>)
Traceback (most recent call last):
  File "/home/m/moonraker-env/lib/python3.9/site-packages/tornado/ioloop.py", line 750, in _run_callback
    ret = callback()
  File "/home/m/moonraker-env/lib/python3.9/site-packages/tornado/simple_httpclient.py", line 287, in <lambda>
    gen.convert_yielded(self.run()), lambda f: f.result()
  File "/home/m/moonraker-env/lib/python3.9/site-packages/tornado/simple_httpclient.py", line 340, in run
    stream = await self.tcp_client.connect(
  File "/home/m/moonraker-env/lib/python3.9/site-packages/tornado/tcpclient.py", line 269, in connect
    addrinfo = await self.resolver.resolve(host, port, af)
  File "/home/m/moonraker-env/lib/python3.9/site-packages/tornado/netutil.py", line 433, in resolve
    for fam, _, _, _, address in await asyncio.get_running_loop().getaddrinfo(
  File "/usr/lib/python3.9/asyncio/base_events.py", line 856, in getaddrinfo
    return await self.run_in_executor(
  File "/usr/lib/python3.9/concurrent/futures/thread.py", line 52, in run
    result = self.fn(*self.args, **self.kwargs)
  File "/usr/lib/python3.9/socket.py", line 953, in getaddrinfo
    for res in _socket.getaddrinfo(host, port, family, type, proto, flags):
socket.gaierror: [Errno -3] Temporary failure in name resolution
2024-05-26 03:11:30,944 [announcements.py:_fetch_moonlight()] - Failed to update subscription 'moonraker-telegram-bot': Timeout while connecting
2024-05-26 03:11:34,988 [ioloop.py:_run_callback()] - Exception in callback functools.partial(<function _HTTPConnection.__init__.<locals>.<lambda> at 0x655b8730>, <Task finished name='Task-9284411' coro=<_HTTPConnection.run() done, defined at /home/m/moonraker-env/lib/python3.9/site-packages/tornado/simple_httpclient.py:290> exception=gaierror(-3, 'Temporary failure in name resolution')>)
Traceback (most recent call last):
  File "/home/m/moonraker-env/lib/python3.9/site-packages/tornado/ioloop.py", line 750, in _run_callback
    ret = callback()
  File "/home/m/moonraker-env/lib/python3.9/site-packages/tornado/simple_httpclient.py", line 287, in <lambda>
    gen.convert_yielded(self.run()), lambda f: f.result()
  File "/home/m/moonraker-env/lib/python3.9/site-packages/tornado/simple_httpclient.py", line 340, in run
    stream = await self.tcp_client.connect(
  File "/home/m/moonraker-env/lib/python3.9/site-packages/tornado/tcpclient.py", line 269, in connect
    addrinfo = await self.resolver.resolve(host, port, af)
  File "/home/m/moonraker-env/lib/python3.9/site-packages/tornado/netutil.py", line 433, in resolve
    for fam, _, _, _, address in await asyncio.get_running_loop().getaddrinfo(
  File "/usr/lib/python3.9/asyncio/base_events.py", line 856, in getaddrinfo
    return await self.run_in_executor(
  File "/usr/lib/python3.9/concurrent/futures/thread.py", line 52, in run
    result = self.fn(*self.args, **self.kwargs)
  File "/usr/lib/python3.9/socket.py", line 953, in getaddrinfo
    for res in _socket.getaddrinfo(host, port, family, type, proto, flags):
socket.gaierror: [Errno -3] Temporary failure in name resolution
2024-05-26 03:11:40,475 [ioloop.py:_run_callback()] - Exception in callback functools.partial(<function _HTTPConnection.__init__.<locals>.<lambda> at 0x6556f730>, <Task finished name='Task-9284452' coro=<_HTTPConnection.run() done, defined at /home/m/moonraker-env/lib/python3.9/site-packages/tornado/simple_httpclient.py:290> exception=gaierror(-3, 'Temporary failure in name resolution')>)
Traceback (most recent call last):
  File "/home/m/moonraker-env/lib/python3.9/site-packages/tornado/ioloop.py", line 750, in _run_callback
    ret = callback()
  File "/home/m/moonraker-env/lib/python3.9/site-packages/tornado/simple_httpclient.py", line 287, in <lambda>
    gen.convert_yielded(self.run()), lambda f: f.result()
  File "/home/m/moonraker-env/lib/python3.9/site-packages/tornado/simple_httpclient.py", line 340, in run
    stream = await self.tcp_client.connect(
  File "/home/m/moonraker-env/lib/python3.9/site-packages/tornado/tcpclient.py", line 269, in connect
    addrinfo = await self.resolver.resolve(host, port, af)
  File "/home/m/moonraker-env/lib/python3.9/site-packages/tornado/netutil.py", line 433, in resolve
    for fam, _, _, _, address in await asyncio.get_running_loop().getaddrinfo(
  File "/usr/lib/python3.9/asyncio/base_events.py", line 856, in getaddrinfo
    return await self.run_in_executor(
  File "/usr/lib/python3.9/concurrent/futures/thread.py", line 52, in run
    result = self.fn(*self.args, **self.kwargs)
  File "/usr/lib/python3.9/socket.py", line 953, in getaddrinfo
    for res in _socket.getaddrinfo(host, port, family, type, proto, flags):
socket.gaierror: [Errno -3] Temporary failure in name resolution
2024-05-26 03:11:45,991 [ioloop.py:_run_callback()] - Exception in callback functools.partial(<function _HTTPConnection.__init__.<locals>.<lambda> at 0x655b8538>, <Task finished name='Task-9284498' coro=<_HTTPConnection.run() done, defined at /home/m/moonraker-env/lib/python3.9/site-packages/tornado/simple_httpclient.py:290> exception=gaierror(-3, 'Temporary failure in name resolution')>)
Traceback (most recent call last):
  File "/home/m/moonraker-env/lib/python3.9/site-packages/tornado/ioloop.py", line 750, in _run_callback
    ret = callback()
  File "/home/m/moonraker-env/lib/python3.9/site-packages/tornado/simple_httpclient.py", line 287, in <lambda>
    gen.convert_yielded(self.run()), lambda f: f.result()
  File "/home/m/moonraker-env/lib/python3.9/site-packages/tornado/simple_httpclient.py", line 340, in run
    stream = await self.tcp_client.connect(
  File "/home/m/moonraker-env/lib/python3.9/site-packages/tornado/tcpclient.py", line 269, in connect
    addrinfo = await self.resolver.resolve(host, port, af)
  File "/home/m/moonraker-env/lib/python3.9/site-packages/tornado/netutil.py", line 433, in resolve
    for fam, _, _, _, address in await asyncio.get_running_loop().getaddrinfo(
  File "/usr/lib/python3.9/asyncio/base_events.py", line 856, in getaddrinfo
    return await self.run_in_executor(
  File "/usr/lib/python3.9/concurrent/futures/thread.py", line 52, in run
    result = self.fn(*self.args, **self.kwargs)
  File "/usr/lib/python3.9/socket.py", line 953, in getaddrinfo
    for res in _socket.getaddrinfo(host, port, family, type, proto, flags):
socket.gaierror: [Errno -3] Temporary failure in name resolution
2024-05-26 03:11:49,475 [ioloop.py:_run_callback()] - Exception in callback functools.partial(<function _HTTPConnection.__init__.<locals>.<lambda> at 0x655b8a00>, <Task finished name='Task-9284566' coro=<_HTTPConnection.run() done, defined at /home/m/moonraker-env/lib/python3.9/site-packages/tornado/simple_httpclient.py:290> exception=gaierror(-3, 'Temporary failure in name resolution')>)
Traceback (most recent call last):
  File "/home/m/moonraker-env/lib/python3.9/site-packages/tornado/ioloop.py", line 750, in _run_callback
    ret = callback()
  File "/home/m/moonraker-env/lib/python3.9/site-packages/tornado/simple_httpclient.py", line 287, in <lambda>
    gen.convert_yielded(self.run()), lambda f: f.result()
  File "/home/m/moonraker-env/lib/python3.9/site-packages/tornado/simple_httpclient.py", line 340, in run
    stream = await self.tcp_client.connect(
  File "/home/m/moonraker-env/lib/python3.9/site-packages/tornado/tcpclient.py", line 269, in connect
    addrinfo = await self.resolver.resolve(host, port, af)
  File "/home/m/moonraker-env/lib/python3.9/site-packages/tornado/netutil.py", line 433, in resolve
    for fam, _, _, _, address in await asyncio.get_running_loop().getaddrinfo(
  File "/usr/lib/python3.9/asyncio/base_events.py", line 856, in getaddrinfo
    return await self.run_in_executor(
  File "/usr/lib/python3.9/concurrent/futures/thread.py", line 52, in run
    result = self.fn(*self.args, **self.kwargs)
  File "/usr/lib/python3.9/socket.py", line 953, in getaddrinfo
    for res in _socket.getaddrinfo(host, port, family, type, proto, flags):
socket.gaierror: [Errno -3] Temporary failure in name resolution
2024-05-26 03:11:54,972 [ioloop.py:_run_callback()] - Exception in callback functools.partial(<function _HTTPConnection.__init__.<locals>.<lambda> at 0x655b8df0>, <Task finished name='Task-9284615' coro=<_HTTPConnection.run() done, defined at /home/m/moonraker-env/lib/python3.9/site-packages/tornado/simple_httpclient.py:290> exception=gaierror(-3, 'Temporary failure in name resolution')>)
Traceback (most recent call last):
  File "/home/m/moonraker-env/lib/python3.9/site-packages/tornado/ioloop.py", line 750, in _run_callback
    ret = callback()
  File "/home/m/moonraker-env/lib/python3.9/site-packages/tornado/simple_httpclient.py", line 287, in <lambda>
    gen.convert_yielded(self.run()), lambda f: f.result()
  File "/home/m/moonraker-env/lib/python3.9/site-packages/tornado/simple_httpclient.py", line 340, in run
    stream = await self.tcp_client.connect(
  File "/home/m/moonraker-env/lib/python3.9/site-packages/tornado/tcpclient.py", line 269, in connect
    addrinfo = await self.resolver.resolve(host, port, af)
  File "/home/m/moonraker-env/lib/python3.9/site-packages/tornado/netutil.py", line 433, in resolve
    for fam, _, _, _, address in await asyncio.get_running_loop().getaddrinfo(
  File "/usr/lib/python3.9/asyncio/base_events.py", line 856, in getaddrinfo
    return await self.run_in_executor(
  File "/usr/lib/python3.9/concurrent/futures/thread.py", line 52, in run
    result = self.fn(*self.args, **self.kwargs)
  File "/usr/lib/python3.9/socket.py", line 953, in getaddrinfo
    for res in _socket.getaddrinfo(host, port, family, type, proto, flags):
socket.gaierror: [Errno -3] Temporary failure in name resolution
2024-05-26 03:12:00,480 [ioloop.py:_run_callback()] - Exception in callback functools.partial(<function _HTTPConnection.__init__.<locals>.<lambda> at 0x655b8928>, <Task finished name='Task-9284681' coro=<_HTTPConnection.run() done, defined at /home/m/moonraker-env/lib/python3.9/site-packages/tornado/simple_httpclient.py:290> exception=gaierror(-3, 'Temporary failure in name resolution')>)
Traceback (most recent call last):
  File "/home/m/moonraker-env/lib/python3.9/site-packages/tornado/ioloop.py", line 750, in _run_callback
    ret = callback()
  File "/home/m/moonraker-env/lib/python3.9/site-packages/tornado/simple_httpclient.py", line 287, in <lambda>
    gen.convert_yielded(self.run()), lambda f: f.result()
  File "/home/m/moonraker-env/lib/python3.9/site-packages/tornado/simple_httpclient.py", line 340, in run
    stream = await self.tcp_client.connect(
  File "/home/m/moonraker-env/lib/python3.9/site-packages/tornado/tcpclient.py", line 269, in connect
    addrinfo = await self.resolver.resolve(host, port, af)
  File "/home/m/moonraker-env/lib/python3.9/site-packages/tornado/netutil.py", line 433, in resolve
    for fam, _, _, _, address in await asyncio.get_running_loop().getaddrinfo(
  File "/usr/lib/python3.9/asyncio/base_events.py", line 856, in getaddrinfo
    return await self.run_in_executor(
  File "/usr/lib/python3.9/concurrent/futures/thread.py", line 52, in run
    result = self.fn(*self.args, **self.kwargs)
  File "/usr/lib/python3.9/socket.py", line 953, in getaddrinfo
    for res in _socket.getaddrinfo(host, port, family, type, proto, flags):
socket.gaierror: [Errno -3] Temporary failure in name resolution
2024-05-26 03:12:05,972 [ioloop.py:_run_callback()] - Exception in callback functools.partial(<function _HTTPConnection.__init__.<locals>.<lambda> at 0x64b874f0>, <Task finished name='Task-9284738' coro=<_HTTPConnection.run() done, defined at /home/m/moonraker-env/lib/python3.9/site-packages/tornado/simple_httpclient.py:290> exception=gaierror(-3, 'Temporary failure in name resolution')>)
Traceback (most recent call last):
  File "/home/m/moonraker-env/lib/python3.9/site-packages/tornado/ioloop.py", line 750, in _run_callback
    ret = callback()
  File "/home/m/moonraker-env/lib/python3.9/site-packages/tornado/simple_httpclient.py", line 287, in <lambda>
    gen.convert_yielded(self.run()), lambda f: f.result()
  File "/home/m/moonraker-env/lib/python3.9/site-packages/tornado/simple_httpclient.py", line 340, in run
    stream = await self.tcp_client.connect(
  File "/home/m/moonraker-env/lib/python3.9/site-packages/tornado/tcpclient.py", line 269, in connect
    addrinfo = await self.resolver.resolve(host, port, af)
  File "/home/m/moonraker-env/lib/python3.9/site-packages/tornado/netutil.py", line 433, in resolve
    for fam, _, _, _, address in await asyncio.get_running_loop().getaddrinfo(
  File "/usr/lib/python3.9/asyncio/base_events.py", line 856, in getaddrinfo
    return await self.run_in_executor(
  File "/usr/lib/python3.9/concurrent/futures/thread.py", line 52, in run
    result = self.fn(*self.args, **self.kwargs)
  File "/usr/lib/python3.9/socket.py", line 953, in getaddrinfo
    for res in _socket.getaddrinfo(host, port, family, type, proto, flags):
socket.gaierror: [Errno -3] Temporary failure in name resolution
2024-05-26 05:00:31,141 [proc_stats.py:_watchdog_callback()] - EVENT LOOP BLOCKED: 5.46 seconds, total blocked count: 10
2024-05-26 05:00:31,343 [proc_stats.py:log_last_stats()] - 
System Time: 1716714024.110001, Usage: 1.27%, Memory: 17560 kB
System Time: 1716714025.111378, Usage: 3.09%, Memory: 17560 kB
System Time: 1716714026.115398, Usage: 1.11%, Memory: 17560 kB
System Time: 1716714027.117754, Usage: 3.42%, Memory: 17560 kB
System Time: 1716714031.231855, Usage: 1.79%, Memory: 17560 kB
2024-05-26 05:02:06,809 [machine.py:_parse_network_interfaces()] - Error processing network update
Traceback (most recent call last):
  File "/home/m/moonraker/moonraker/components/machine.py", line 673, in _parse_network_interfaces
    resp = await self.addr_cmd.run_with_response(log_complete=False)
  File "/home/m/moonraker/moonraker/components/shell_command.py", line 277, in run_with_response
    raise ShellCommandError(
moonraker.components.shell_command.ShellCommandError: Error running shell command: 'ip -json -det address'
